<?xml version="1.0" ?>
<!-- =================================================================================== -->
<!-- |    This document was autogenerated by xacro from av.urdf.xacro                  | -->
<!-- |    EDITING THIS FILE BY HAND IS NOT RECOMMENDED                                 | -->
<!-- =================================================================================== -->
<robot name="av">
  <material name="dark_grey">
    <color rgba="0.2 0.2 0.2 1.0"/>
  </material>
  <material name="grey">
    <color rgba="0.5 0.5 0.5 1.0"/>
  </material>
  <link name="left_wheel_link">
    <visual>
      <origin rpy="0 0 0" xyz="0 0 0"/>
      <geometry>
        <cylinder length="0.045" radius="0.055"/>
      </geometry>
      <material name="grey"/>
    </visual>
    <collision>
      <origin rpy="0 0 0" xyz="0 0 0"/>
      <geometry>
        <!-- prevent wheel drift in simulation with a sphere -->
        <sphere radius="0.055"/>
      </geometry>
    </collision>
    <inertial>
      <mass value="0.32"/>
      <inertia ixx="0.000296" ixy="0.0" ixz="0.0" iyy="0.000296" iyz="0.0" izz="0.000484"/>
    </inertial>
  </link>
  <joint name="left_wheel_joint" type="continuous">
    <axis xyz="0 0 1"/>
    <origin rpy="-1.5707963267948966 0 0" xyz="0 0.145 0.055"/>
    <parent link="base_link"/>
    <child link="left_wheel_link"/>
    <limit effort="100.0" velocity="100.0"/>
  </joint>
  <link name="right_wheel_link">
    <visual>
      <origin rpy="0 0 0" xyz="0 0 0"/>
      <geometry>
        <cylinder length="0.045" radius="0.055"/>
      </geometry>
      <material name="grey"/>
    </visual>
    <collision>
      <origin rpy="0 0 0" xyz="0 0 0"/>
      <geometry>
        <!-- prevent wheel drift in simulation with a sphere -->
        <sphere radius="0.055"/>
      </geometry>
    </collision>
    <inertial>
      <mass value="0.32"/>
      <inertia ixx="0.000296" ixy="0.0" ixz="0.0" iyy="0.000296" iyz="0.0" izz="0.000484"/>
    </inertial>
  </link>
  <joint name="right_wheel_joint" type="continuous">
    <axis xyz="0 0 1"/>
    <origin rpy="-1.5707963267948966 0 0" xyz="0 -0.145 0.055"/>
    <parent link="base_link"/>
    <child link="right_wheel_link"/>
    <limit effort="100.0" velocity="100.0"/>
  </joint>
  <link name="left_caster_wheel_link">
    <visual>
      <origin rpy="0 0 0" xyz="0 0 0"/>
      <geometry>
        <cylinder length="0.04" radius="0.05"/>
      </geometry>
      <material name="grey"/>
    </visual>
    <collision>
      <origin rpy="0 0 0" xyz="0 0 0"/>
      <geometry>
        <!-- prevent wheel drift in simulation with a sphere -->
        <sphere radius="0.055"/>
      </geometry>
    </collision>
    <inertial>
      <mass value="0.0"/>
      <inertia ixx="0.0" ixy="0.0" ixz="0.0" iyy="0.0" iyz="0.0" izz="0.0"/>
    </inertial>
  </link>
  <joint name="left_caster_wheel_joint" type="fixed">
    <axis xyz="0 0 1"/>
    <origin rpy="-1.5707963267948966 0 0" xyz="0.45 0.145 0.05"/>
    <parent link="base_link"/>
    <child link="left_caster_wheel_link"/>
    <limit effort="100.0" velocity="100.0"/>
  </joint>
  <link name="right_caster_wheel_link">
    <visual>
      <origin rpy="0 0 0" xyz="0 0 0"/>
      <geometry>
        <cylinder length="0.04" radius="0.05"/>
      </geometry>
      <material name="grey"/>
    </visual>
    <collision>
      <origin rpy="0 0 0" xyz="0 0 0"/>
      <geometry>
        <!-- prevent wheel drift in simulation with a sphere -->
        <sphere radius="0.055"/>
      </geometry>
    </collision>
    <inertial>
      <mass value="0.0"/>
      <inertia ixx="0.0" ixy="0.0" ixz="0.0" iyy="0.0" iyz="0.0" izz="0.0"/>
    </inertial>
  </link>
  <joint name="right_caster_wheel_joint" type="fixed">
    <axis xyz="0 0 1"/>
    <origin rpy="-1.5707963267948966 0 0" xyz="0.45 -0.145 0.05"/>
    <parent link="base_link"/>
    <child link="right_caster_wheel_link"/>
    <limit effort="100.0" velocity="100.0"/>
  </joint>
  <link name="chassis">
    <visual>
      <origin rpy="0 0 0" xyz="0 0 0"/>
      <geometry>
        <box size="0.6 0.4 0.03"/>
      </geometry>
      <material name="dark_grey"/>
    </visual>
    <collision>
      <origin rpy="0 0 0" xyz="0 0 0"/>
      <geometry>
        <box size="0.6 0.4 0.03"/>
      </geometry>
    </collision>
    <inertial>
      <mass value="18.0"/>
      <inertia ixx="0.24135000000000006" ixy="0.0" ixz="0.0" iyy="0.54135" iyz="0.0" izz="0.7799999999999999"/>
    </inertial>
  </link>
  <joint name="chassis_joint" type="fixed">
    <origin rpy="0 0 0" xyz="0.23 0 0.095"/>
    <parent link="base_link"/>
    <child link="chassis"/>
  </joint>
  <link name="base_link"/>
  <gazebo reference="left_wheel_link">
    <material>Gazebo/Grey</material>
    <surface>
      <friction>
        <ode>
          <mu>0.005</mu>
          <mu2>0.00005</mu2>
        </ode>
      </friction>
    </surface>
  </gazebo>
  <gazebo reference="right_wheel_link">
    <material>Gazebo/Grey</material>
    <surface>
      <friction>
        <ode>
          <mu>0.005</mu>
          <mu2>0.00005</mu2>
        </ode>
      </friction>
    </surface>
  </gazebo>
  <gazebo reference="left_caster_wheel_link">
    <material>Gazebo/Grey</material>
    <surface>
      <friction>
        <ode>
          <mu>0.001</mu>
          <mu2>0.001</mu2>
        </ode>
      </friction>
    </surface>
  </gazebo>
  <gazebo reference="right_caster_wheel_link">
    <material>Gazebo/Grey</material>
    <surface>
      <friction>
        <ode>
          <mu>0.001</mu>
          <mu2>0.001</mu2>
        </ode>
      </friction>
    </surface>
  </gazebo>
  <gazebo reference="chassis">
    <material>Gazebo/DarkGrey</material>
  </gazebo>
  <gazebo>
    <plugin filename="libgazebo_ros_diff_drive.so" name="diff_drive">
      <left_joint>left_wheel_joint</left_joint>
      <right_joint>right_wheel_joint</right_joint>
      <wheel_separation>0.29</wheel_separation>
      <wheel_diameter>0.11</wheel_diameter>
      <max_wheel_torque>100.0</max_wheel_torque>
      <max_wheel_acceleration>100.0</max_wheel_acceleration>
      <odometry_frame>odom</odometry_frame>
      <robot_base_frame>base_link</robot_base_frame>
      <publish_odom>true</publish_odom>
      <publish_odom_tf>true</publish_odom_tf>
      <publish_wheel_tf>true</publish_wheel_tf>
    </plugin>
  </gazebo>
</robot>
