<?xml version="1.0" ?>
<!-- =================================================================================== -->
<!-- |    This document was autogenerated by xacro from av.urdf.xacro                  | -->
<!-- |    EDITING THIS FILE BY HAND IS NOT RECOMMENDED                                 | -->
<!-- =================================================================================== -->
<robot name="av">
  <material name="dark_grey">
    <color rgba="0.2 0.2 0.2 1.0"/>
  </material>
  <material name="grey">
    <color rgba="0.5 0.5 0.5 1.0"/>
  </material>
  <link name="left_wheel_link">
    <visual>
      <origin rpy="0 0 0" xyz="0 0 0"/>
      <geometry>
        <cylinder length="0.045" radius="0.055"/>
      </geometry>
      <material name="grey"/>
    </visual>
    <collision>
      <origin rpy="0 0 0" xyz="0 0 0"/>
      <geometry>
        <!-- prevent wheel drift in simulation with a sphere -->
        <sphere radius="0.055"/>
      </geometry>
    </collision>
    <inertial>
      <mass value="0.32"/>
      <inertia ixx="0.000296" ixy="0.0" ixz="0.0" iyy="0.000296" iyz="0.0" izz="0.000484"/>
    </inertial>
  </link>
  <joint name="left_wheel_joint" type="continuous">
    <axis xyz="0 0 1"/>
    <origin rpy="-1.5707963267948966 0 0" xyz="0 0.145 0.055"/>
    <parent link="base_link"/>
    <child link="left_wheel_link"/>
    <limit effort="100.0" velocity="100.0"/>
  </joint>
  <link name="right_wheel_link">
    <visual>
      <origin rpy="0 0 0" xyz="0 0 0"/>
      <geometry>
        <cylinder length="0.045" radius="0.055"/>
      </geometry>
      <material name="grey"/>
    </visual>
    <collision>
      <origin rpy="0 0 0" xyz="0 0 0"/>
      <geometry>
        <!-- prevent wheel drift in simulation with a sphere -->
        <sphere radius="0.055"/>
      </geometry>
    </collision>
    <inertial>
      <mass value="0.32"/>
      <inertia ixx="0.000296" ixy="0.0" ixz="0.0" iyy="0.000296" iyz="0.0" izz="0.000484"/>
    </inertial>
  </link>
  <joint name="right_wheel_joint" type="continuous">
    <axis xyz="0 0 1"/>
    <origin rpy="-1.5707963267948966 0 0" xyz="0 -0.145 0.055"/>
    <parent link="base_link"/>
    <child link="right_wheel_link"/>
    <limit effort="100.0" velocity="100.0"/>
  </joint>
  <link name="left_caster_wheel_link">
    <visual>
      <origin rpy="0 0 0" xyz="0 0 0"/>
      <geometry>
        <cylinder length="0.04" radius="0.05"/>
      </geometry>
      <material name="grey"/>
    </visual>
    <collision>
      <origin rpy="0 0 0" xyz="0 0 0"/>
      <geometry>
        <!-- prevent wheel drift in simulation with a sphere -->
        <sphere radius="0.055"/>
      </geometry>
    </collision>
    <inertial>
      <mass value="0.1"/>
      <inertia ixx="7.583333333333335e-05" ixy="0.0" ixz="0.0" iyy="7.583333333333335e-05" iyz="0.0" izz="0.00012500000000000003"/>
    </inertial>
  </link>
  <joint name="left_caster_wheel_joint" type="continuous">
    <axis xyz="0 0 1"/>
    <origin rpy="-1.5707963267948966 0 0" xyz="0.45 0.145 0.05"/>
    <parent link="base_link"/>
    <child link="left_caster_wheel_link"/>
    <limit effort="100.0" velocity="100.0"/>
  </joint>
  <link name="right_caster_wheel_link">
    <visual>
      <origin rpy="0 0 0" xyz="0 0 0"/>
      <geometry>
        <cylinder length="0.04" radius="0.05"/>
      </geometry>
      <material name="grey"/>
    </visual>
    <collision>
      <origin rpy="0 0 0" xyz="0 0 0"/>
      <geometry>
        <!-- prevent wheel drift in simulation with a sphere -->
        <sphere radius="0.055"/>
      </geometry>
    </collision>
    <inertial>
      <mass value="0.1"/>
      <inertia ixx="7.583333333333335e-05" ixy="0.0" ixz="0.0" iyy="7.583333333333335e-05" iyz="0.0" izz="0.00012500000000000003"/>
    </inertial>
  </link>
  <joint name="right_caster_wheel_joint" type="continuous">
    <axis xyz="0 0 1"/>
    <origin rpy="-1.5707963267948966 0 0" xyz="0.45 -0.145 0.05"/>
    <parent link="base_link"/>
    <child link="right_caster_wheel_link"/>
    <limit effort="100.0" velocity="100.0"/>
  </joint>
  <link name="chassis">
    <visual>
      <origin rpy="0 0 0" xyz="0 0 0"/>
      <geometry>
        <box size="0.6 0.4 0.03"/>
      </geometry>
      <material name="dark_grey"/>
    </visual>
    <collision>
      <origin rpy="0 0 0" xyz="0 0 0"/>
      <geometry>
        <box size="0.6 0.4 0.03"/>
      </geometry>
    </collision>
    <inertial>
      <mass value="18.0"/>
      <inertia ixx="0.24135000000000006" ixy="0.0" ixz="0.0" iyy="0.54135" iyz="0.0" izz="0.7799999999999999"/>
    </inertial>
  </link>
  <joint name="chassis_joint" type="fixed">
    <origin rpy="0 0 0" xyz="0.23 0 0.095"/>
    <parent link="base_link"/>
    <child link="chassis"/>
  </joint>
  <link name="base_link"/>
  <gazebo reference="left_wheel_link">
    <material>Gazebo/Grey</material>
    <surface>
      <friction>
        <ode>
          <fdir>0 0 1</fdir>
          <mu>0.001</mu>
          <mu2>0.001</mu2>
        </ode>
      </friction>
    </surface>
  </gazebo>
  <gazebo reference="right_wheel_link">
    <material>Gazebo/Grey</material>
    <surface>
      <friction>
        <ode>
          <fdir>0 0 1</fdir>
          <mu>0.001</mu>
          <mu2>0.001</mu2>
        </ode>
      </friction>
    </surface>
  </gazebo>
  <gazebo reference="left_caster_wheel_link">
    <material>Gazebo/Grey</material>
    <surface>
      <friction>
        <ode>
          <fdir>0 0 1</fdir>
          <mu>0.001</mu>
          <mu2>0.001</mu2>
        </ode>
      </friction>
    </surface>
  </gazebo>
  <gazebo reference="right_caster_wheel_link">
    <material>Gazebo/Grey</material>
    <surface>
      <friction>
        <ode>
          <fdir>0 0 1</fdir>
          <mu>0.001</mu>
          <mu2>0.001</mu2>
        </ode>
      </friction>
    </surface>
  </gazebo>
  <gazebo reference="chassis">
    <material>Gazebo/DarkGrey</material>
  </gazebo>
  <!-- controls -->
  <gazebo>
    <plugin filename="libgazebo_ros_diff_drive.so" name="diff_drive">
      <left_joint>left_wheel_joint</left_joint>
      <right_joint>right_wheel_joint</right_joint>
      <wheel_separation>0.29</wheel_separation>
      <wheel_diameter>0.11</wheel_diameter>
      <max_wheel_torque>100.0</max_wheel_torque>
      <max_wheel_acceleration>100.0</max_wheel_acceleration>
      <odometry_frame>odom</odometry_frame>
      <robot_base_frame>base_link</robot_base_frame>
      <publish_odom>true</publish_odom>
      <publish_odom_tf>true</publish_odom_tf>
      <publish_wheel_tf>true</publish_wheel_tf>
    </plugin>
    <plugin filename="libgazebo_ros_joint_state_publisher.so" name="gazebo_ros_joint_state_publisher">
      <publish_selected_only>true</publish_selected_only>
      <joint_name>left_caster_wheel_joint</joint_name>
      <joint_name>right_caster_wheel_joint</joint_name>
      <update_rate>100.0</update_rate>
    </plugin>
  </gazebo>
  <!-- sensors -->
  <gazebo reference="laser_frame">
    <material>Gazebo/Black</material>
    <sensor name="laser" type="ray">
      <pose>0 0 0 0 0 0</pose>
      <visualize>true</visualize>
      <update_rate>10.0</update_rate>
      <ray>
        <scan>
          <horizontal>
            <samples>720</samples>
            <resolution>1</resolution>
            <min_angle>-2.09439</min_angle>
            <max_angle>2.09439</max_angle>
          </horizontal>
        </scan>
        <range>
          <min>0.1</min>
          <max>12</max>
          <resolution>0.01</resolution>
        </range>
      </ray>
      <plugin filename="libgazebo_ros_ray_sensor.so" name="laser_controller">
        <ros>
          <argument>~/out:=scan</argument>
        </ros>
        <output_type>sensor_msgs/LaserScan</output_type>
        <frame_name>laser_frame</frame_name>
      </plugin>
    </sensor>
  </gazebo>
  <gazebo reference="camera_link">
    <material>Gazebo/Black</material>
    <sensor name="camera" type="depth">
      <pose>0 0 0 0 0 0</pose>
      <visualize>true</visualize>
      <update_rate>10.0</update_rate>
      <!-- RealSense D435i-->
      <camera>
        <!-- RGB camera 69 degrees -->
        <horizontal_fov>1.204</horizontal_fov>
        <image>
          <width>640</width>
          <height>480</height>
          <format>B8G8R8</format>
        </image>
        <clip>
          <near>0.05</near>
          <far>100.0</far>
        </clip>
      </camera>
      <plugin filename="libgazebo_ros_camera.so" name="camera_controller">
        <frame_name>camera_link_optical</frame_name>
      </plugin>
    </sensor>
  </gazebo>
  <material name="black">
    <color rgba="0.0 0.0 0.0 1.0"/>
  </material>
  <link name="laser_frame">
    <visual>
      <geometry>
        <cylinder length="0.05" radius="0.035"/>
      </geometry>
      <material name="black"/>
    </visual>
    <collision>
      <geometry>
        <cylinder length="0.05" radius="0.035"/>
      </geometry>
    </collision>
    <inertia>
      <inertial>
        <mass value="0.2"/>
        <inertia ixx="0.00010291666666666668" ixy="0.0" ixz="0.0" iyy="0.00010291666666666668" iyz="0.0" izz="0.00012250000000000002"/>
      </inertial>
    </inertia>
  </link>
  <joint name="laser_joint" type="fixed">
    <origin rpy="0 0 0" xyz="0.25 0 0.03"/>
    <parent link="chassis"/>
    <child link="laser_frame"/>
  </joint>
  <!-- camera -->
  <link name="camera_link" type="fixed">
    <visual>
      <geometry>
        <box size="0.025 0.09 0.025"/>
      </geometry>
      <material name="black"/>
    </visual>
  </link>
  <joint name="camera_joint" type="fixed">
    <origin rpy="0 0 0" xyz="-0.05 0 0.15"/>
    <parent link="chassis"/>
    <child link="camera_link"/>
  </joint>
  <link name="camera_link_optical"/>
  <joint name="camera_joint_optical" type="fixed">
    <origin rpy="-1.5707963267948966 0 -1.5707963267948966" xyz="0 0 0"/>
    <parent link="camera_link"/>
    <child link="camera_link_optical"/>
  </joint>
</robot>
