<?xml version="1.0" ?>
<!-- =================================================================================== -->
<!-- |    This document was autogenerated by xacro from av.urdf.xacro                  | -->
<!-- |    EDITING THIS FILE BY HAND IS NOT RECOMMENDED                                 | -->
<!-- =================================================================================== -->
<robot name="av">
  <material name="dark_grey">
    <color rgba="0.2 0.2 0.2 1.0"/>
  </material>
  <material name="grey">
    <color rgba="0.5 0.5 0.5 1.0"/>
  </material>
  <link name="left_wheel_link">
    <visual>
      <origin rpy="0 0 0" xyz="0 0 0"/>
      <geometry>
        <cylinder length="0.045" radius="0.055"/>
      </geometry>
      <material name="grey"/>
    </visual>
    <collision>
      <origin rpy="-1.5707963267948966 0 0" xyz="0 0 0"/>
      <geometry>
        <cylinder length="0.045" radius="0.055"/>
      </geometry>
    </collision>
    <inertial>
      <mass value="0.32"/>
      <inertia ixx="0.000296" ixy="0.0" ixz="0.0" iyy="0.000296" iyz="0.0" izz="0.000484"/>
    </inertial>
  </link>
  <joint name="left_wheel_joint" type="continuous">
    <axis xyz="0 0 1"/>
    <origin rpy="-1.5707963267948966 0 0" xyz="0 0.145 0.055"/>
    <parent link="base_link"/>
    <child link="left_wheel_link"/>
    <limit effort="1.0" velocity="10.0"/>
  </joint>
  <link name="right_wheel_link">
    <visual>
      <origin rpy="0 0 0" xyz="0 0 0"/>
      <geometry>
        <cylinder length="0.045" radius="0.055"/>
      </geometry>
      <material name="grey"/>
    </visual>
    <collision>
      <origin rpy="-1.5707963267948966 0 0" xyz="0 0 0"/>
      <geometry>
        <cylinder length="0.045" radius="0.055"/>
      </geometry>
    </collision>
    <inertial>
      <mass value="0.32"/>
      <inertia ixx="0.000296" ixy="0.0" ixz="0.0" iyy="0.000296" iyz="0.0" izz="0.000484"/>
    </inertial>
  </link>
  <joint name="right_wheel_joint" type="continuous">
    <axis xyz="0 0 1"/>
    <origin rpy="-1.5707963267948966 0 0" xyz="0 -0.145 0.055"/>
    <parent link="base_link"/>
    <child link="right_wheel_link"/>
    <limit effort="1.0" velocity="10.0"/>
  </joint>
  <link name="left_caster_wheel_link">
    <visual>
      <origin rpy="0 0 0" xyz="0 0 0"/>
      <geometry>
        <cylinder length="0.04" radius="0.05"/>
      </geometry>
      <material name="grey"/>
    </visual>
    <collision>
      <origin rpy="-1.5707963267948966 0 0" xyz="0 0 0"/>
      <geometry>
        <cylinder length="0.045" radius="0.055"/>
      </geometry>
    </collision>
    <inertial>
      <mass value="0.32"/>
      <inertia ixx="0.0" ixy="0.0" ixz="0.0" iyy="0.0" iyz="0.0" izz="0.0"/>
    </inertial>
  </link>
  <joint name="left_caster_wheel_joint" type="fixed">
    <axis xyz="0 0 1"/>
    <origin rpy="-1.5707963267948966 0 0" xyz="0.45 0.145 0.05"/>
    <parent link="base_link"/>
    <child link="left_caster_wheel_link"/>
    <limit effort="1.0" velocity="10.0"/>
  </joint>
  <link name="right_caster_wheel_link">
    <visual>
      <origin rpy="0 0 0" xyz="0 0 0"/>
      <geometry>
        <cylinder length="0.04" radius="0.05"/>
      </geometry>
      <material name="grey"/>
    </visual>
    <collision>
      <origin rpy="-1.5707963267948966 0 0" xyz="0 0 0"/>
      <geometry>
        <cylinder length="0.045" radius="0.055"/>
      </geometry>
    </collision>
    <inertial>
      <mass value="0.32"/>
      <inertia ixx="0.0" ixy="0.0" ixz="0.0" iyy="0.0" iyz="0.0" izz="0.0"/>
    </inertial>
  </link>
  <joint name="right_caster_wheel_joint" type="fixed">
    <axis xyz="0 0 1"/>
    <origin rpy="-1.5707963267948966 0 0" xyz="0.45 -0.145 0.05"/>
    <parent link="base_link"/>
    <child link="right_caster_wheel_link"/>
    <limit effort="1.0" velocity="10.0"/>
  </joint>
  <link name="chassis">
    <visual>
      <origin rpy="0 0 0" xyz="0 0 0"/>
      <geometry>
        <box size="0.6 0.4 0.03"/>
      </geometry>
      <material name="dark_grey"/>
    </visual>
    <collision>
      <origin rpy="0 0 0" xyz="0 0 0"/>
      <geometry>
        <box size="0.6 0.4 0.03"/>
      </geometry>
    </collision>
    <inertial>
      <mass value="18.0"/>
      <inertia ixx="0.24135000000000006" ixy="0.0" ixz="0.0" iyy="0.54135" iyz="0.0" izz="0.7799999999999999"/>
    </inertial>
  </link>
  <joint name="chassis_joint" type="fixed">
    <origin rpy="0 0 0" xyz="0.23 0 0.095"/>
    <parent link="base_link"/>
    <child link="chassis"/>
  </joint>
  <link name="base_link"/>
</robot>
